#### 异常处理  
------
### 异常Exception  
------
## 错误Error  
逻辑错误：算法写错了，例如加法写成了减法  
笔误：例如变量名写错了，语法错误  
函数或类使用错误，其实这也是与逻辑错误  
总之，错误是可以避免的  

## 异常Exception
本意就是意外情况  
这个有个前提，没有出现上面的错误，也就是说程序写的没有问题，但是在某些情况下，会出现一些意外，导致程序无法正常的执行下去。  
例如open函数操作一个文件，文件不存在，或者创建建一个文件已经存在了，或者访问一个网络文件，突然断电了，这就是异常，是个意外情况。  

## 错误和异常  
在高级编程语言中，一般都有错误和异常的概念。异常是可以捕获,且可以被处理的.但是错误是不能被捕获的.  

*举例:*  
对比异常与错误  
```py
# with open('aaa') as f:
#     pass

# 异常
'''
Traceback (most recent call last):
  File "1.对比异常与错误.py", line 8, in <module>
    with open('aaa') as f:
FileNotFoundError: [Errno 2] No such file or directory: 'aaa'
'''
##########################################################
# def 0A():
#     pass
#错误:

'''
    def 0A():
        ^
SyntaxError: invalid syntax
'''
```

一个健壮的程序  
尽可能的避免错误  
尽可能的捕获、处理各种异常  

---

### 产生异常
* 产生：
    - raise 渔具现实的抛出异常  
    - Python解释器自己检测到异常，并引发它  


``` py
def foo():
    print('before')
    print(1/0)
    print('after')

foo()


'''
输出结果为:
before
Traceback (most recent call last):
     print(1/0)
ZeroDivisionError: division by zero

'''

# def bar():
#     print('before')
#     raise Exception('my exception') #raise 主动抛出异常
#     print('after')
#
# bar()

'''
输出结果为:
before
Traceback (most recent call last):
    raise Exception('my exception') #raise 主动抛出异常
Exception: my exception
'''
```
程序会在异常抛出的地方中段执行，如果不捕获，程序就会提前结束(其实是终止当前线程的执行)  
### 捕获异常  
---
```py
try:
    特定捕获的异常代码块
except [异常类型]:
    异常处理代码块
```
代码例子:
```py
def foo():
    try:
        print('befor')
        c = 1/0
        print('after')
    except:
        print('error')

    print('catch the exception')
foo()
print('end','='*30)
```

*输出结果为:*
```py
befor
error
catch the exception
end ==============================

```
上例执行到`c = 1/0`的时候产生了异常并抛出,由于使用了try...except语句捕捉到了这个异常,异常之后语句将不再执行,壮而执行对应的except部分语句,最后执行try...except之外的语句.  

## 捕获指定类型的异常  

```py 
def foo():
    try:
        print('before')
        print(1/0)
        print('after')
    except ArithmeticError: #指定捕获的异常类型(算法错误)
        print('error')

    print('catch the exeption')
foo()
print('end','+'*39)
```
*输出的结果为:*
```py
before
error
catch the exeption
end +++++++++++++++++++++++++++++++++++++++

```

#### 异常类及其继承层次  
```py
# Python异常的继承
BaseException 
    SystemExit
    KeyboardInterrupt
    GeneratorExit
    Exception 
        StopIteration
        StopAsyncIteration
        ArithmeticError 
            FloatingPointError
            OverflowError
            ZeroDivisionError
        AssertionError
        AttributeError
        BufferError
        EOFError
        ImportError 
            ModuleNotFoundError
        LookupError 
            IndexError
            KeyError
        MemoryError
        NameError 
            UnboundLocalError
        OSError 
            BlockingIOError
            ChildProcessError
            ConnectionError 
                BrokenPipeError
                ConnectionAbortedError
                ConnectionRefusedError
                ConnectionResetError
            FileExistsError
            FileNotFoundError
            InterruptedError
            IsADirectoryError
            NotADirectoryError
            PermissionError
            ProcessLookupError
            TimeoutError
        ReferenceError
        RuntimeError 
            NotImplementedError
            RecursionError
        SyntaxError 
            IndentationError
            TabError
        SystemError
        TypeError
        ValueError 
            UnicodeError
            UnicodeDecodeError
            UnicodeEncodeError
            UnicodeTranslateError
        Warning 
            DeprecationWarning
            PendingDeprecationWarning
            RuntimeWarning
            SyntaxWarning
            UserWarning
            FutureWarning
            ImportWarning
            UnicodeWarning
            BytesWarning
            ResourceWarning

```
---

#### BaseException及子类    
## BaseException  
所有内建异常类的基本是BaseException  

## SystemExit  
sys.exit()函数引发的异常,异常不捕获处理,就直接交给了Python解释器,解释器直接退出.  

例子:  
```py
import sys

print('before')
sys.exit(1)
print('Sysexit')
print('outer') #是否能执行?
```
结果:  
    上面的代码在exit之后都不执行了,应为这里已经是代码遗产退出了  

例子:  
```py
import sys

try :
    sys.exit(2)
except SystemExit: #换成了Exception 能否捕获?
    print('Systxit')
print('outer') #是否执行?
```
结果:  
    他们都能执行,应为这里做了异常处理了.异常一旦被捕获了代码就汇率正常的执行下去.

总结:  
    如果except语句捕获了该异常,则继续向后面执行,如果没有捕获住该异常SystemExit,解释器直接退出程序.  
    注意捕获后程序的退出码的变化.  

## keyboardInterrupt  
对应的捕获用户中断行为Ctrl+C  
```py 

try:
    import time
    while True:
        time.sleep(1)
        print('111')
except KeyboardInterrupt:
    print('ctrl + c')
print('+'*30)
```

*输出的结果为:*  
```py 
C:\Users\Administrator\Desktop\面向对象,类\6.异常处理>python 6.KeyboardInterrupt.py
111
111
111
ctrl + c
++++++++++++++++++++++++++++++

```
---

### Exception及子类  
Exception是所有内建的,非系统退出的基类,自定义异常类应该继承自它.  
## SyntaxError 语法错误  
*例子*
```py 
def a():
    try:
        01 = 5
    except:
        pass
#错误
```

*输出的结果为:*  
```py 
    01 = 5
     ^
SyntaxError: invalid token
```
## ArithmeticeError  
所有算术计算引发的异常,其子类有除零异常等.  

## LookupErrot
使用映射的键或者序列的索引无效引起的异常的基类,IndexError,KeyError  

## 自定义异常类  
从Exception继承的类  

---
*例子*
```py 
class MyException(Exception):
    pass

try:
    raise MyException()

except MyException:#捕获自定义异常类
    print('catch the exception')
```

*输出的结果为:*  
```py 
catch the exception

```
---

#### 多重捕获  
except可以指定捕获的类型,捕获多种异常  

*例子3*
```py 
import sys

class MyException(Exception):pass

try:
    a = 1/0
    raise MyException()
    open('a')
    sys.exit(1)
except ZeroDivisionError:
    print('zero')

except ArithmeticError:
    print('ari')

except MyException:
    print('myexc')

except Exception:
    print('exc')

except:
    print('sysexit')
```

*输出的结果为:*  
```py 
zero
```
* 捕获规则:
    - 捕获是从上到下依次比较,如果匹配了,就执行匹配的except语句块.  
    - 如果被一个except语句块捕获,其他except语句就不会再次捕获了  
    - 如果没有被任何一个except所捕获,那么则该异常继续向外抛出  

捕获的原则  
    从小到大,从具体到宽泛  
    还有就是捕获的异常劲量往小了写,应为,具体的异常类可以使用具体的类的方法,越靠近子类那么,它的可用方法也就越多,就越有利于我们分析程序.  

---
#### as子句  
---

*例子*
```py 
#这个例子中raise能抛出什么样的异常?
class A:pass

try:
    #1/0
    raise 1
    # raise 'abc'
    # raise {}
    # raise A
    # raise A()
except:
    print('catch the exception')
```

*输出的结果为:*  
```py 
catch the exception
```
raise 真的什么类型都能抛出吗?
在上面的例子中,无论抛出什么样的异常,我们看到的永远都是'catch the exception'  
我们却并不知道他实际上的异常是什么!所以我们并不能对象对应的异常去做处理.  
被抛出的异常,应该是异常类的实例,如何捕获这个对象呢?  
这里就要用到了as语句了  
---

*例子*
```py 
class MyException(Exception):
    def __init__(self,code,message):
        self.code = code
        self.message = message

try:
    raise MyException
except MyException as e:
    print('catch my exception')
except:
    print('catch other ~~~')

#运行结果是什么?为什么?
```

*输出的结果为:*  
```py 
catch other ~~~
```
运行结果之所以是这样,那是因为,我们在抛出自定义的错误的时候,我们自定义的类也报错了,应为没有传入参数.所以才会输出这样的结果.  

---
修改后的代码如下:
*例子*
```py 
class MyException(Exception):
    def __init__(self,code,message):
        self.code = code
        self.message = message

try:
    raise MyException
except MyException as e:
    print('catch my exception')
except Exception as e:
    print(e)
```

*输出的结果为:*  
```py 
__init__() missing 2 required positional arguments: 'code' and 'message'
```
由上面报错我们可以得知,raise后面的类是无参数构造实例,因此需要两个参数.  

---
在上面的例子上传入参数:
*例子*
```py 
#传入参数
class MyException(Exception):
    def __init__(self,code,message):
        self.code = code
        self.message = message

try:
    raise MyException(200,'error')
except MyException as e:
    print('catch my exception')
except Exception as e:
    print(e)

```

*输出的结果为:*  
```py 
catch my exception
```
总结:  
**raise 语句**
raise后面要求应该是BaseException类的**子类或者实例**.如果是类将被**无参实例化**.  
raise后面什么都没有,表示抛出最近一个被激活的异常没如果没有被激活的异常,则抛出类型异常.这种方式很少用.  
---

# finally子句

---
finally
最终,即最后一定要执行的,try...finally语句块中,不管是否发生了异常,都要执行finally的部分  

*例子*
```py 
try:
    f = open('test.txt')
except FileNotFoundError as e:
    print('{} {} {}'.format(e.__class__,e.errno,e.strerror))
finally:
    print('清理工作')
    f.close()
```

*输出的结果为:*  
```py 
<class 'FileNotFoundError'> 2
Traceback (most recent call last):
清理工作
    f.close()
NameError: name 'f' is not defined
```
注意上例中的f的作用域,解决的办法是在外部定义的f
finally中一般放置资源的清理,示范工作的语句
---

*例子*
```py 
f = None
try:
    f = open('test.txt')
except FileNotFoundError as e:
    print('{} {}'.format(e.__class__,e.errno,e.strerror))
finally:
    print('清理工作')
    f.close()
```

*输出的结果为:*  
```py 
<class 'FileNotFoundError'> 2
清理工作
Traceback (most recent call last):
    f.close()
AttributeError: 'NoneType' object has no attribute 'close'
```
从上面的两个例子可以看出我们在外部定义变量f之后他的错误类型就变成了AttributeError了.  
其实我们最初是想要打开一个文件的,如果文件不存在应该是filenotfound的,然而这之后出现了一个个的的报错,当我们确定了报错了之后就能很明确的使用finally来再次捕捉异常了.  

---
再次捕捉异常:
*例子*
```py 
f = None
try:
    f = open('test.txt')
except FileNotFoundError as e:
    print('{}'.format(e)
finally:
    print('清理工作')
    try:
        f.close()
    except Exception as e:
        print(e)
```

*输出的结果为:*  
```py 
[Errno 2] No such file or directory: 'test.txt'
清理工作
'NoneType' object has no attribute 'close'
```
这样整个代码都可以顺利的执行完毕了  

---
# finall的执行时机  
*例子*
```py 
#测试
def foo():
    try:
        print('try')
        return 3
    except:
        print('except')
        return 2
    finally:
        print('finally')
        return 1
    print('==')
print(foo())
```

*输出的结果为:*  
```py 
try
finally
1
```
* 分析:
    - 进入try,执行return 3,虽然函数要返回,但是finally是无论如何都要执行的,所以回去执行print('finally')和return 1,函数返回,1被压在栈顶,所以返回1.  
    - 简单的说,函数的返回值取决于最后一个执行的return语句,而finally则是try...finally中最后执行的语句块.  

---

# 异常的传递  
*例子*
```py 
def foo():
    return 1/0

def bar():
    print('bar start')
    foo()
    print('bar end')

bar()
```

*输出的结果为:*  
```py 
bar start
Traceback (most recent call last):
    return 1/0
ZeroDivisionError: division by zero
```
* 分析:
    - bar函数调用了foo函数,foo产生了异常,没有被捕捉,就传递到了bar函数中.  
    - 异常总是向外抛出的,如果外层没有处理这个异常,就会继续往外抛出.  
    - 如果内层捕捉到了并处理了异常,外部就不能捕捉到了.  
    - 如果带了最外层还是没有被处理,就会中断异常所在的线程执行.注意整个程序结束的返回状态.  

---

*例子*
```py 
#线程中测试异常

import threading
import time

def foo():
    return 1/0

def bar():
    time.sleep(3) #3秒后抛出异常
    print('bar start')
    foo()
    print('bar end')

t = threading.Thread(target=bar)
t.start()

while True:
    time.sleep(1)
    print('Everything OK')
    print(threading.enumerate()) #打印当前所有线程
```

*输出的结果为:*  
```py 
Everything OK
[<_MainThread(MainThread, started 8312)>, <Thread(Thread-1, started 2052)>]
Everything OK
[<_MainThread(MainThread, started 8312)>, <Thread(Thread-1, started 2052)>]
Everything OK
[<_MainThread(MainThread, started 8312)>, <Thread(Thread-1, started 2052)>]
bar start
Exception in thread Thread-1:
Traceback (most recent call last):
    return 1/0
ZeroDivisionError: division by zero

Everything OK
[<_MainThread(MainThread, started 8312)>]
Everything OK
[<_MainThread(MainThread, started 8312)>]
Everything OK
[<_MainThread(MainThread, started 8312)>]
Everything OK
[<_MainThread(MainThread, started 8312)>]
Everything OK
[<_MainThread(MainThread, started 8312)>]
Everything OK
[<_MainThread(MainThread, started 8312)>]
Everything OK
[<_MainThread(MainThread, started 8312)>]
Everything OK
[<_MainThread(MainThread, started 8312)>]
Everything OK
[<_MainThread(MainThread, started 8312)>]
Everything OK
[<_MainThread(MainThread, started 8312)>]
Everything OK
[<_MainThread(MainThread, started 8312)>]
Everything OK
[<_MainThread(MainThread, started 8312)>]
Everything OK
[<_MainThread(MainThread, started 8312)>]
Everything OK
[<_MainThread(MainThread, started 8312)>]
Everything OK
[<_MainThread(MainThread, started 8312)>]
Everything OK
[<_MainThread(MainThread, started 8312)>]
Everything OK
[<_MainThread(MainThread, started 8312)>]
Everything OK
[<_MainThread(MainThread, started 8312)>]
Everything OK
[<_MainThread(MainThread, started 8312)>]
```
分析:  
    上面的例子中同时开启了两个线程,但是异常捕捉的进程没有抓住异常,会导致捕捉异常的线程直接崩溃掉,但是我们的主线程还在,空留了一个没有什么用的进程,却没有干活,这样就白白的浪费资源而已.  

---
# try嵌套
*例子*
```py 
try:
    try:
        ret = 1/0
    except KeyError as e:
        print(e)
    finally:
        print('inner fin')
except:
    print('outer catch')
finally:
    print('outer fin')
```

*输出的结果为:*  
```py 
inner fin
outer catch
outer fin

```
结论:  
    内部捕获不到的异常,会向外抛出,  
    但是如果内层有finally且有return,break语句,则异常就不会继续往外抛出.   


---

*finally 和break中断异常的向外抛出的例子*
```py 
def foo():
    try:
        ret = 1/0
    except KeyError as e:
        print(e)
    finally:
        print('inner fin')
        return #异常被丢弃,程序继续往下执行

try:
    foo()
except:
    print('outer catch')
finally:
    print('outer fin')

```

*输出的结果为:*  
```py 
inner fin
outer fin
```
分析:
    按照正常的异常抛出顺序,输出的结果应该是inner fin和outer catch,才对,然而却不是,应为异常被丢弃了,导致了没有异常被捕捉从而直接到了finally  

结论就是:异常在return的时候被丢弃了

---

# 异常的捕获时机  
1.立即捕获  
需要立即返回一个明确的结果  


```py
def parse_int(s):
    try:
        return  int(s)
    except:
        return 0
print(parse_int('s'))

```

*输出的结果为:*  
```py 
0
```
直接返回了一个结果,程序结束.  

---
2,边界捕获  
封装产生了边界.  

例如,写一个模块,用户调用这个模块的时候捕获了异常,模块内部不需要捕获,异常处理,一旦内部处理了,外部调用者就无法感知了,  

例如,open函数,出现了异常交给调用者处理,文件存在了,就不用再创建了,看是否修改还是删除  

例如,自己写了一个类,使用了open函数,但是出现了异常不知道如何处理,就继续的向外层抛出,一般来说,最外层就是边检,必须处理这个异常了,否者线程就会崩溃退出  

---
# else子句  

```py
try:
    ret = 1*0
except ArithmeticError as e:
    print(e)
else:
    print('ok')
finally:
    print('fin')
```

*输出的结果为:*  
```py 
ok
fin
```
总结:  
    else子句的执行条件是,在**没有任何异常发生**的时候才执行的.  

---

# 总结  

```py
try:
    <语句> #运行别的代码
except <异常类>:
    <语句块> #捕获某种类型的异常

except <异常类>:
    <语句块> #捕获某种类型的异常
else:
    <语句> #在没有异常的时候触发

finally:
    <语句> #退出try时总会执行
```
### try的工作原理  
* 
    - 1.如果try中语句执行时发生异常,搜索except子句,并执行第一个匹配该异常的except子句.  
    - 2.如果try中语句执行时发生异常,却没有匹配的except子句,异常将被传递到外层的try,如果外层不处理这个异常,异常将继续往外传递,如果都不处理,则会传递到最外层,如果还没有处理,就终止异常所在的线程,  
    - 3.如果在try执行是没有发生异常,如有else子句,可执行else子句中的语句,  
    - 4.无论try中是否发生异常,finally子句都将最终执行.  